Workbook
Name Slicer_Brand: #N/A
Name Slicer_City: #N/A

Sheet Sheet1
A1: Transaction ID | B1: Date | C1: Day Name | D1: Brand | E1: Units Sold | F1: Price Per Unit | G1: price | H1: Customer Name | I1: City | J1: Payment Method | K1: Customer Ratings | L1: Mobile Model | M1: name | N1: month
A2: 3187 | B2: =DATE(#REF!,#REF!,#REF!) -> #REF! | C2: Thursday | D2: Vivo | E2: 1 | F2: 68589.4 | G2: =F2*E2 -> 68589.4 | H2: Aditya Alva | I2: Delhi | J2: Cash | K2: 2 | L2: Vivo Y51 | M2: january | N2: =PROPER($M$2) -> January | O2: {=SUM(IF(TEXT($B:$B,"MMMM")=N2,$F:$F))} -> #REF!
A3: 305 | B3: =DATE(#REF!,#REF!,#REF!) -> #REF! | C3: Monday | D3: OnePlus | E3: 2 | F3: 13374.8 | G3: =F3*E3 -> 26749.6 | H3: Aditya Arora | I3: Ranchi | J3: Debit Card | K3: 5 | L3: OnePlus 9 | M3: february | N3: =PROPER(M3) -> February
A4: 1721 | B4: =DATE(#REF!,#REF!,#REF!) -> #REF! | C4: Friday | D4: OnePlus | E4: 8 | F4: 65893.9 | G4: =F4*E4 -> 527151.2 | H4: Aditya Arora | I4: Madurai | J4: Credit Card | K4: 5 | L4: OnePlus 8T | M4: march | N4: =PROPER(M4) -> March
A5: 219 | B5: =DATE(#REF!,#REF!,#REF!) -> #REF! | C5: Friday | D5: Samsung | E5: 6 | F5: 38806.47 | G5: =F5*E5 -> 232838.82 | H5: Aditya Deshmukh | I5: Jodhpur | J5: Cash | K5: 4 | L5: Galaxy A51 | M5: april | N5: =PROPER(M5) -> April
A6: 3695 | B6: =DATE(#REF!,#REF!,#REF!) -> #REF! | C6: Wednesday | D6: Xiaomi | E6: 2 | F6: 69810.93 | G6: =F6*E6 -> 139621.86 | H6: Aditya Deshmukh | I6: Chennai | J6: Cash | K6: 5 | L6: Redmi 9 | M6: may | N6: =PROPER(M6) -> May
A7: 508 | B7: =DATE(#REF!,#REF!,#REF!) -> #REF! | C7: Monday | D7: OnePlus | E7: 2 | F7: 12197.78 | G7: =F7*E7 -> 24395.56 | H7: Aditya Iyer | I7: Ludhiana | J7: Cash | K7: 3 | L7: OnePlus Nord | M7: june | N7: =PROPER(M7) -> June
A8: 1247 | B8: =DATE(#REF!,#REF!,#REF!) -> #REF! | C8: Friday | D8: Samsung | E8: 7 | F8: 48953.73 | G8: =F8*E8 -> 342676.11 | H8: Aditya Iyer | I8: Bhopal | J8: Cash | K8: 4 | L8: Galaxy Note 20 | M8: july | N8: =PROPER(M8) -> July
A9: 2057 | B9: =DATE(#REF!,#REF!,#REF!) -> #REF! | C9: Tuesday | D9: Samsung | E9: 8 | F9: 54017.31 | G9: =F9*E9 -> 432138.48 | H9: Aditya Iyer | I9: Rajkot | J9: Credit Card | K9: 4 | L9: Galaxy S21 | M9: august | N9: =PROPER(M9) -> August
A10: 3380 | B10: =DATE(#REF!,#REF!,#REF!) -> #REF! | C10: Thursday | D10: Vivo | E10: 7 | F10: 12518.23 | G10: =F10*E10 -> 87627.61 | H10: Aditya Iyer | I10: Bhopal | J10: Cash | K10: 2 | L10: Vivo Y51 | M10: september | N10: =PROPER(M10) -> September
A11: 820 | B11: =DATE(#REF!,#REF!,#REF!) -> #REF! | C11: Tuesday | D11: OnePlus | E11: 7 | F11: 11999.39 | G11: =F11*E11 -> 83995.73 | H11: Aditya Jain | I11: Mumbai | J11: Credit Card | K11: 2 | L11: OnePlus Nord | M11: october | N11: =PROPER(M11) -> October
A12: 2159 | B12: =DATE(#REF!,#REF!,#REF!) -> #REF! | C12: Tuesday | D12: Samsung | E12: 6 | F12: 23613.15 | G12: =F12*E12 -> 141678.9 | H12: Aditya Jain | I12: Ranchi | J12: Credit Card | K12: 4 | L12: Galaxy Note 20 | M12: november | N12: =PROPER(M12) -> November
A13: 3040 | B13: =DATE(#REF!,#REF!,#REF!) -> #REF! | C13: Thursday | D13: Samsung | E13: 4 | F13: 54574.52 | G13: =F13*E13 -> 218298.08 | H13: Aditya Jain | I13: Rajkot | J13: Credit Card | K13: 3 | L13: Galaxy Note 20 | M13: december | N13: =PROPER(M13) -> December
A14: 3082 | B14: =DATE(#REF!,#REF!,#REF!) -> #REF! | C14: Monday | D14: Apple | E14: 7 | F14: 37749.41 | G14: =F14*E14 -> 264245.87 | H14: Aditya Jain | I14: Gorakhpur | J14: Debit Card | K14: 1 | L14: iPhone 12
A15: 3153 | B15: =DATE(#REF!,#REF!,#REF!) -> #REF! | C15: Monday | D15: Xiaomi | E15: 2 | F15: 34655.29 | G15: =F15*E15 -> 69310.58 | H15: Aditya Jain | I15: Delhi | J15: UPI | K15: 5 | L15: Redmi 9
A16: 3540 | B16: =DATE(#REF!,#REF!,#REF!) -> #REF! | C16: Saturday | D16: Vivo | E16: 9 | F16: 33510.58 | G16: =F16*E16 -> 301595.22 | H16: Aditya Jain | I16: Delhi | J16: Credit Card | K16: 4 | L16: Vivo Y51
A17: 1147 | B17: =DATE(#REF!,#REF!,#REF!) -> #REF! | C17: Thursday | D17: Apple | E17: 3 | F17: 64583.61 | G17: =F17*E17 -> 193750.83 | H17: Aditya Joshi | I17: Delhi | J17: Credit Card | K17: 4 | L17: iPhone 12
A18: 1297 | B18: =DATE(#REF!,#REF!,#REF!) -> #REF! | C18: Friday | D18: Samsung | E18: 6 | F18: 22655.64 | G18: =F18*E18 -> 135933.84 | H18: Aditya Joshi | I18: Delhi | J18: Debit Card | K18: 5 | L18: Galaxy A51
A19: 1325 | B19: =DATE(#REF!,#REF!,#REF!) -> #REF! | C19: Saturday | D19: Apple | E19: 8 | F19: 39382.24 | G19: =F19*E19 -> 315057.92 | H19: Aditya Joshi | I19: Mumbai | J19: Debit Card | K19: 3 | L19: iPhone 12
A20: 2089 | B20: =DATE(#REF!,#REF!,#REF!) -> #REF! | C20: Thursday | D20: Xiaomi | E20: 8 | F20: 34127.87 | G20: =F20*E20 -> 273022.96 | H20: Aditya Joshi | I20: Mumbai | J20: Cash | K20: 4 | L20: Redmi 9
A21: 3663 | B21: =DATE(#REF!,#REF!,#REF!) -> #REF! | C21: Sunday | D21: Apple | E21: 3 | F21: 12317 | G21: =F21*E21 -> 36951 | H21: Aditya Joshi | I21: Mumbai | J21: UPI | K21: 4 | L21: iPhone SE
A22: 835 | B22: =DATE(#REF!,#REF!,#REF!) -> #REF! | C22: Saturday | D22: Vivo | E22: 4 | F22: 44490.34 | G22: =F22*E22 -> 177961.36 | H22: Aditya Kulkarni | I22: Kolkata | J22: Credit Card | K22: 5 | L22: Vivo V20
A23: 1798 | B23: =DATE(#REF!,#REF!,#REF!) -> #REF! | C23: Sunday | D23: Vivo | E23: 6 | F23: 35001.69 | G23: =F23*E23 -> 210010.14 | H23: Aditya Kulkarni | I23: Mumbai | J23: Credit Card | K23: 1 | L23: Vivo Y51
A24: 3035 | B24: =DATE(#REF!,#REF!,#REF!) -> #REF! | C24: Tuesday | D24: Samsung | E24: 5 | F24: 46512.08 | G24: =F24*E24 -> 232560.4 | H24: Aditya Kulkarni | I24: Kanpur | J24: UPI | K24: 3 | L24: Galaxy Note 20
A25: 742 | B25: =DATE(#REF!,#REF!,#REF!) -> #REF! | C25: Monday | D25: Apple | E25: 3 | F25: 30324.99 | G25: =F25*E25 -> 90974.97 | H25: Aditya Luthra | I25: Bangalore | J25: Debit Card | K25: 5 | L25: iPhone 11
... A3836: 1895 | B3836: =DATE(#REF!,#REF!,#REF!) -> #REF! | C3836: Saturday | D3836: Xiaomi | E3836: 8 | F3836: 49179.56 | G3836: =F3836*E3836 -> 393436.48 | H3836: Yogesh Siddiqui | I3836: Kanpur | J3836: UPI | K3836: 5 | L3836: Mi 11

Sheet Sheet3
A3: Sum of Units Sold | C3: Sum of Price Per Unit
A4: 19150 | B4: =GETPIVOTDATA("Units Sold",$A$3) -> 19150 | C4: 1.5383733e+08
A6: Average of Customer Ratings
A7: 3.69309
B9: 5
A10: otol | B10: =A7 -> 3.69309
A11: less | B11: =5-B10 -> 1.30691
H12: apple | I12: =K24 -> 3.7075351 | K12: OnePlus | L12: =L25 -> 3.6822917 | N12: Samsung | O12: =L26 -> 3.7045161
H13: Overall | I13: 4 | K13: Overall | L13: =I13 -> 4 | N13: Overall | O13: =L13 -> 4
B14: Customer Name | C14: Sum of Price Per Unit | D14: Sum of Units Sold
B15: Isha Desai | C15: 332216.72 | D15: 52
B16: Kavita Teja | C16: 449061.87 | D16: 52
B17: Lata Shah | C17: 422325.87 | D17: 54 | I17: Vivo | J17: =L27 -> 3.6488251 | K17: Xiaomi | L17: =L28 -> 3.7227456
B18: Manoj Jain | C18: 369342.91 | D18: 56 | J18: 4 | L18: =J18 -> 4
B19: Prashant Gupta | C19: 440264.95 | D19: 74
B20: Grand Total | C20: 2013212.3 | D20: 288
D23: Brand | E23: Sum of Units Sold | F23: =E23 -> Sum of Units Sold | J23: Brand | K23: Average of Customer Ratings
D24: Xiaomi | E24: 3664 | F24: =E24 -> 3664 | I24: =Sheet3!O29 -> 32100621 | J24: Apple | K24: 3.7075351 | M24: 5
D25: Vivo | E25: 3801 | F25: =E25 -> 3801 | I25: =Sheet3!O30 -> 30752041 | J25: OnePlus | K25: 3.6822917 | L25: =K25 -> 3.6822917
D26: OnePlus | E26: 3830 | F26: =E26 -> 3830 | I26: =Sheet3!O31 -> 31266514 | J26: Samsung | K26: 3.7045161 | L26: =K26 -> 3.7045161
D27: Samsung | E27: 3923 | F27: =E27 -> 3923 | I27: =Sheet3!O32 -> 30207858 | J27: Vivo | K27: 3.6488251 | L27: =K27 -> 3.6488251
D28: Apple | E28: 3932 | F28: =E28 -> 3932 | I28: =Sheet3!O33 -> 29510297 | J28: Xiaomi | K28: 3.7227456 | L28: =K28 -> 3.7227456 | N28: Brand | O28: Sum of Price Per Unit | Q28: Payment Method | R28: Count of Payment Method
D29: Grand Total | E29: 19150 | F29: =E29 -> 19150 | I29: =H29 -> 0 | J29: Grand Total | K29: 3.69309 | L29: 5 | N29: Apple | O29: 32100621 | Q29: Cash | R29: 929
N30: OnePlus | O30: 30752041 | Q30: Credit Card | R30: 947
N31: Samsung | O31: 31266514 | Q31: Debit Card | R31: 948
E32: Month | F32: Sum of Units Sold | N32: Vivo | O32: 30207858 | Q32: UPI | R32: 1011
E33: 1 | F33: 1672 | H33: City | I33: Sum of Price Per Unit | J33: City | K33: Total sale Amount | N33: Xiaomi | O33: 29510297 | Q33: Grand Total | R33: 3835
A34: Row Labels | B34: Sum of price | E34: 2 | F34: 1451 | H34: Bangalore | I34: 5573446.3 | J34: =H34 -> Bangalore | K34: =I34 -> 5573446.3
A35: January | B35: 68589.4 | E35: 3 | F35: 1696 | H35: Bhopal | I35: 4820511.4 | J35: =H35 -> Bhopal | K35: =I35 -> 4820511.4
A36: February | B36: 26749.6 | E36: 4 | F36: 1528 | H36: Chennai | I36: 5297245.7 | J36: =H36 -> Chennai | K36: =I36 -> 5297245.7
A37: March | B37: 527151.2 | E37: 5 | F37: 1625 | H37: Coimbatore | I37: 4727427.7 | J37: =H37 -> Coimbatore | K37: =I37 -> 4727427.7
A38: April | B38: 232838.82 | E38: 6 | F38: 1597 | H38: Delhi | I38: 40269644 | J38: =H38 -> Delhi | K38: =I38 -> 40269644
A39: May | B39: 139621.86 | E39: 7 | F39: 1700 | H39: Gorakhpur | I39: 5075978.5 | J39: =H39 -> Gorakhpur | K39: =I39 -> 5075978.5
A40: June | B40: 24395.56 | E40: 8 | F40: 1592 | H40: Hyderabad | I40: 5368084.8 | J40: =H40 -> Hyderabad | K40: =I40 -> 5368084.8
A41: July | B41: 342676.11 | E41: 9 | F41: 1521 | H41: Indore | I41: 5045392.8 | J41: =H41 -> Indore | K41: =I41 -> 5045392.8
A42: August | B42: 432138.48 | E42: 10 | F42: 1577 | H42: Jodhpur | I42: 5038264.6 | J42: =H42 -> Jodhpur | K42: =I42 -> 5038264.6
A43: September | B43: 87627.61 | E43: 11 | F43: 1582 | H43: Kanpur | I43: 4991907 | J43: =H43 -> Kanpur | K43: =I43 -> 4991907
A44: October | B44: 83995.73 | E44: 12 | F44: 1609 | H44: Kolkata | I44: 5080599.4 | J44: =H44 -> Kolkata | K44: =I44 -> 5080599.4
A45: November | B45: 141678.9 | E45: Grand Total | F45: 19150 | H45: Lucknow | I45: 5207830.5 | J45: =H45 -> Lucknow | K45: =I45 -> 5207830.5
A46: December | B46: 218298.08 | H46: Ludhiana | I46: 4885492.7 | J46: =H46 -> Ludhiana | K46: =I46 -> 4885492.7
...

Sheet Sheet2
